Workbook
Name order_AccountCol: 'ORDER SHEET'!$A:$A
Name order_CNHCol: 'ORDER SHEET'!$Q:$Q
Name order_ColourCol: 'ORDER SHEET'!$N:$N
Name order_CustNameCol: 'ORDER SHEET'!$B:$B
Name order_DetStart: 'ORDER SHEET'!$A$7
Name order_DropCol: 'ORDER SHEET'!$G:$G
Name order_FinishCol: 'ORDER SHEET'!$M:$M
Name order_MaterialCol: 'ORDER SHEET'!$I:$I
Name order_OrderNumCol: 'ORDER SHEET'!$C:$C
Name order_Qty: 'ORDER SHEET'!$R:$R
Name order_SheetNo: 'ORDER SHEET'!$S$2
Name order_TapeSplineCol: 'ORDER SHEET'!$K:$K
Name order_WidthCol: 'ORDER SHEET'!$F:$F

Sheet ORDER SHEET
A1: Shadelite Blinds (Vic) Pty. Ltd. | S1: ORDER SHEET NO.
S2: 9
A3: 18 Allied Drive Tullamarine VIC 3044 | E3: Phone: (03) 9330 2713 Fax: (03) 93352570 | N3: DATE:
A4: Email: Shadeliteblinds@gmail.com | E4: Orders: Orders.Shadeliteblinds@gmail.com
A5: ACCOUNT | B5: CUSTOMER NAME | C5: BLIND NO | I5: MATERIAL | N5: COMPONENTRY COLOUR | O5: CHAIN SIZE/ | P5: SIDE | S5: ACCESSORIES
E6: ROOM | F6: WIDTH | G6: DROP | I6: RANGE | J6: COLOUR | K6: TAPE | L6: ROLL | M6: FINISH | O6: OPERATION | P6: WDR | Q6: CHN | R6: QTY | S6: & NOTES
A7: BLINDS4U | B7: Chris | C7: 1 OF 18 | E7: LG1/1 | F7: 824 | G7: 1800 | I7: SOLARCOOL 5% | J7: BEIGE GREY | K7: TAPE | M7: SILVER | N7: S WHITE | O7: 750 | P7: R | Q7: M | R7: 1 | S7: ORDERED
A8: BLINDS4U | B8: Chris | C8: 2 OF 18 | E8: LG1/2 | F8: 824 | G8: 1800 | I8: SOLARCOOL 5% | J8: BEIGE GREY | K8: TAPE | M8: SILVER | N8: S WHITE | O8: 750 | P8: R | Q8: M | R8: 1
A9: BLINDS4U | B9: Chris | C9: 3 OF 18 | E9: LG 1/3 | F9: 822 | G9: 1800 | I9: SOLARCOOL 5% | J9: BEIGE GREY | K9: TAPE | M9: SILVER | N9: S WHITE | O9: 750 | P9: L | Q9: M | R9: 1
A10: BLINDS4U | B10: Chris | C10: 4 OF 18 | E10: S/Door | F10: 1794 | G10: 2100 | I10: SOLARCOOL 5% | J10: BEIGE GREY | K10: TAPE | L10: OR | M10: SILVER | N10: WHITE | O10: SWIVEL 750 | P10: R | Q10: M | R10: 1 | S10: S/L Dbl Bkt
A11: BLINDS4U | B11: Chris | C11: 5 OF 18 | E11: Kitc | F11: 1572 | G11: 1000 | I11: SOLARCOOL 5% | J11: BEIGE GREY | K11: TAPE | L11: OR | M11: SILVER | N11: WHITE | O11: SWIVEL 750 | P11: R | Q11: M | R11: 1 | S11: S/L Dbl Bkt
A12: BLINDS4U | B12: Chris | C12: 6 OF 18 | E12: Bed 1/1 | F12: 811 | G12: 1000 | I12: SOLARCOOL 5% | J12: BEIGE GREY | K12: TAPE | M12: SILVER | N12: S WHITE | O12: 750 | P12: R | Q12: M | R12: 1
A13: BLINDS4U | B13: Chris | C13: 7 OF 18 | E13: Bed1/2 | F13: 811 | G13: 1000 | I13: SOLARCOOL 5% | J13: BEIGE GREY | K13: TAPE | M13: SILVER | N13: S WHITE | O13: 750 | P13: L | Q13: M | R13: 1
A14: BLINDS4U | B14: Chris | C14: 8 OF 18 | E14: Bed 2 | F14: 1762 | G14: 1200 | I14: SOLARCOOL 5% | J14: BEIGE GREY | K14: TAPE | M14: SILVER | N14: S WHITE | O14: 750 | P14: R | Q14: M | R14: 1
A15: BLINDS4U | B15: Chris | C15: 9 OF 18 | E15: Lg1/1 | F15: 975 | G15: 1800 | I15: VIBE | J15: Terrace | K15: TAPE | M15: SILVER | N15: S WHITE | O15: 750 | P15: R | Q15: M | R15: 1 | S15: GOT
A16: BLINDS4U | B16: Chris | C16: 10 OF 18 | E16: Lg1/2 | F16: 975 | G16: 1800 | I16: VIBE | J16: Terrace | K16: TAPE | M16: SILVER | N16: S WHITE | O16: 750 | P16: R | Q16: M | R16: 1
A17: BLINDS4U | B17: Chris | C17: 11 OF 18 | E17: Lg1/3 | F17: 967 | G17: 1800 | I17: VIBE | J17: Terrace | K17: TAPE | M17: SILVER | N17: S WHITE | O17: 750 | P17: L | Q17: M | R17: 1
A18: BLINDS4U | B18: Chris | C18: 12 OF 18 | E18: S/door | F18: 1794 | G18: 2100 | I18: VIBE | J18: Terrace | K18: TAPE | M18: SILVER | N18: WHITE | O18: SWIVEL 750 | P18: R | Q18: M | R18: 1
A19: BLINDS4U | B19: Chris | C19: 13 OF 18 | E19: Kitc | F19: 1572 | G19: 1000 | I19: VIBE | J19: Terrace | K19: TAPE | M19: SILVER | N19: WHITE | O19: SWIVEL 750 | P19: R | Q19: M | R19: 1
A20: BLINDS4U | B20: Chris | C20: 14 OF 18 | E20: Ldy | F20: 1786 | G20: 1000 | I20: VIBE | J20: Terrace | K20: TAPE | M20: SILVER | N20: S WHITE | O20: 750 | P20: R | Q20: M | R20: 1
A21: BLINDS4U | B21: Chris | C21: 15 OF 18 | E21: bed 1/1 | F21: 960 | G21: 1000 | I21: VIBE | J21: Terrace | K21: TAPE | M21: SILVER | N21: S WHITE | O21: 750 | P21: R | Q21: M | R21: 1
A22: BLINDS4U | B22: Chris | C22: 16 OF 18 | E22: Bed 1/2 | F22: 958 | G22: 1000 | I22: VIBE | J22: Terrace | K22: TAPE | M22: SILVER | N22: S WHITE | O22: 750 | P22: L | Q22: M | R22: 1
A23: BLINDS4U | B23: Chris | C23: 17 OF 18 | E23: Bed 2 | F23: 1910 | G23: 1200 | I23: VIBE | J23: Terrace | K23: TAPE | M23: SILVER | N23: S WHITE | O23: 750 | P23: R | Q23: M | R23: 1
A24: BLINDS4U | B24: Chris | C24: 18 OF 18 | E24: Door | F24: 397 | G24: 2100 | I24: VIBE | J24: Terrace | K24: TAPE | M24: SILVER | N24: S WHITE | O24: 750 | P24: L | Q24: M | R24: 1
A25: BLINDS4U | B25: Chris | I25: 2X RHS SLIMLINE COMBOS
A26: BLINDS4U | B26: Chris | I26: 14X S WHITE BRACKETS
A27: BLINDS4U | B27: Joanne | C27: 1 OF 1 | E27: BED1 | F27: 2407 | G27: 2100 | I27: VIBE | J27: BIRCH | K27: TAPE | L27: OR | M27: WHITE | N27: S WHITE | O27: 1000 | P27: L | Q27: M | R27: 1 | S27: GOT
A28: Bayview Blinds | B28: Edithvale | C28: 1 OF 1 | E28: Bedroom | F28: 1448 | G28: 1500 | I28: VIBE | J28: CLOUD | K28: TAPE | M28: SILVER | N28: S WHITE | O28: 1250 | P28: L | Q28: M | R28: 1 | S28: GOT
A29: Bayview Blinds | B29: Bay street | C29: 1 OF 7 | E29: Dining | F29: 1673 | G29: 2400 | I29: SOLARCOOL 5% | J29: WHITE | K29: TAPE | M29: SILVER | N29: S WHITE | O29: 1500 | P29: L | Q29: M | R29: 1 | S29: ORDERED
A30: Bayview Blinds | B30: Bay street | C30: 2 OF 7 | E30: Dining | F30: 1673 | G30: 2400 | I30: SOLARCOOL 5% | J30: WHITE | K30: TAPE | M30: SILVER | N30: S WHITE | O30: 1500 | P30: R | Q30: M | R30: 1
A31: Bayview Blinds | B31: Bay street | C31: 3 OF 7 | E31: Lounge | F31: 1670 | G31: 2400 | I31: SOLARCOOL 5% | J31: WHITE | K31: TAPE | M31: SILVER | N31: S WHITE | O31: 1500 | P31: L | Q31: M | R31: 1
A32: Bayview Blinds | B32: Bay street | C32: 4 OF 7 | E32: Lounge | F32: 1670 | G32: 2400 | I32: SOLARCOOL 5% | J32: WHITE | K32: TAPE | M32: SILVER | N32: S WHITE | O32: 1500 | P32: R | Q32: M | R32: 1
A33: Bayview Blinds | B33: Bay street | C33: 5 OF 7 | E33: Bedroom 1 | F33: 1915 | G33: 2400 | I33: VIBE | J33: CLOUD | K33: TAPE | M33: SILVER | N33: S WHITE | O33: 1500 | P33: L | Q33: M | R33: 1 | S33: GOT
A34: Bayview Blinds | B34: Bay street | C34: 6 OF 7 | E34: Bedroom 2 | F34: 1020 | G34: 2400 | I34: VIBE | J34: CLOUD | K34: TAPE | M34: SILVER | N34: S WHITE | O34: 1500 | P34: L | Q34: M | R34: 1
A35: Bayview Blinds | B35: Bay street | C35: 7 OF 7 | E35: Bedroom 2 | F35: 1020 | G35: 2400 | I35: VIBE | J35: CLOUD | K35: TAPE | M35: SILVER | N35: S WHITE | O35: 1500 | P35: R | Q35: M | R35: 1
A36: Bayview Blinds | B36: Bay street | I36: 7X S WHITE BRACKETS

Sheet CTRL
A1: SILVER RAIL
A2: WHITE RAIL
A3: BLACK RAIL
A4: BIRCH RAIL
A5: RIVERGUM RAIL
A6: CHAMPAGNE RAIL
A7: JASPER RAIL
A8: STEEL PEARL RAIL
A9: CHROME RAIL
A10: PLAIN
A11: FANCY
A12: D30 White
... A14: D30 Silver

Sheet LABELS
A1: ='ORDER SHEET'!$E$7 -> LG1/1 | B1: ='ORDER SHEET'!$F$7&"x"&'ORDER SHEET'!$G$7 -> 824x1800 | C1: =IF('ORDER SHEET'!$L$7="OR","OR","-") -> - | D1: ='ORDER SHEET'!$R$7 -> 1
C2: ='ORDER SHEET'!$M$7 -> SILVER | D2: ='ORDER SHEET'!$P$7 -> R | E2: ='ORDER SHEET'!$C$7 -> 1 OF 18
A3: ='ORDER SHEET'!$A$7 -> BLINDS4U | B3: ='ORDER SHEET'!$B$7 -> Chris | C3: ='ORDER SHEET'!$I$7 & " " & 'ORDER SHEET'!$J$7 -> SOLARCOOL 5% BEIGE GREY | D3: ='ORDER SHEET'!$Q$7 -> M
D4: ='ORDER SHEET'!$O$7 -> 750 | E4: ='ORDER SHEET'!$N$7&" "&"ACC" -> S WHITE ACC
A5: ='ORDER SHEET'!$E$8 -> LG1/2 | B5: ='ORDER SHEET'!$F$8&"x"&'ORDER SHEET'!$G$8 -> 824x1800 | C5: =IF('ORDER SHEET'!$L$8="OR","OR","-") -> - | D5: ='ORDER SHEET'!$R$8 -> 1
C6: ='ORDER SHEET'!$M$8 -> SILVER | D6: ='ORDER SHEET'!$P$8 -> R | E6: ='ORDER SHEET'!$C$8 -> 2 OF 18
A7: ='ORDER SHEET'!$A$8 -> BLINDS4U | B7: ='ORDER SHEET'!$B$8 -> Chris | C7: ='ORDER SHEET'!$I$8 & " " & 'ORDER SHEET'!$J$8 -> SOLARCOOL 5% BEIGE GREY | D7: ='ORDER SHEET'!$Q$8 -> M
D8: ='ORDER SHEET'!$O$8 -> 750 | E8: ='ORDER SHEET'!$N$8&" "&"ACC" -> S WHITE ACC
A9: ='ORDER SHEET'!$E$9 -> LG 1/3 | B9: ='ORDER SHEET'!$F$9&"x"&'ORDER SHEET'!$G$9 -> 822x1800 | C9: =IF('ORDER SHEET'!$L$9="OR","OR","-") -> - | D9: ='ORDER SHEET'!$R$9 -> 1
C10: ='ORDER SHEET'!$M$9 -> SILVER | D10: ='ORDER SHEET'!$P$9 -> L | E10: ='ORDER SHEET'!$C$9 -> 3 OF 18
A11: ='ORDER SHEET'!$A$9 -> BLINDS4U | B11: ='ORDER SHEET'!$B$9 -> Chris | C11: ='ORDER SHEET'!$I$9 & " " & 'ORDER SHEET'!$J$9 -> SOLARCOOL 5% BEIGE GREY | D11: ='ORDER SHEET'!$Q$9 -> M
D12: ='ORDER SHEET'!$O$9 -> 750 | E12: ='ORDER SHEET'!$N$9&" "&"ACC" -> S WHITE ACC
A13: ='ORDER SHEET'!$E$10 -> S/Door | B13: ='ORDER SHEET'!$F$10&"x"&'ORDER SHEET'!$G$10 -> 1794x2100 | C13: =IF('ORDER SHEET'!$L$10="OR","OR","-") -> OR | D13: ='ORDER SHEET'!$R$10 -> 1
C14: ='ORDER SHEET'!$M$10 -> SILVER | D14: ='ORDER SHEET'!$P$10 -> R | E14: ='ORDER SHEET'!$C$10 -> 4 OF 18
A15: ='ORDER SHEET'!$A$10 -> BLINDS4U | B15: ='ORDER SHEET'!$B$10 -> Chris | C15: ='ORDER SHEET'!$I$10 & " " & 'ORDER SHEET'!$J$10 -> SOLARCOOL 5% BEIGE GREY | D15: ='ORDER SHEET'!$Q$10 -> M
D16: ='ORDER SHEET'!$O$10 -> SWIVEL 750 | E16: ='ORDER SHEET'!$N$10&" "&"ACC" -> WHITE ACC
A17: ='ORDER SHEET'!$E$11 -> Kitc | B17: ='ORDER SHEET'!$F$11&"x"&'ORDER SHEET'!$G$11 -> 1572x1000 | C17: =IF('ORDER SHEET'!$L$11="OR","OR","-") -> OR | D17: ='ORDER SHEET'!$R$11 -> 1
C18: ='ORDER SHEET'!$M$11 -> SILVER | D18: ='ORDER SHEET'!$P$11 -> R | E18: ='ORDER SHEET'!$C$11 -> 5 OF 18
A19: ='ORDER SHEET'!$A$11 -> BLINDS4U | B19: ='ORDER SHEET'!$B$11 -> Chris | C19: ='ORDER SHEET'!$I$11 & " " & 'ORDER SHEET'!$J$11 -> SOLARCOOL 5% BEIGE GREY | D19: ='ORDER SHEET'!$Q$11 -> M
D20: ='ORDER SHEET'!$O$11 -> SWIVEL 750 | E20: ='ORDER SHEET'!$N$11&" "&"ACC" -> WHITE ACC
A21: ='ORDER SHEET'!$E$12 -> Bed 1/1 | B21: ='ORDER SHEET'!$F$12&"x"&'ORDER SHEET'!$G$12 -> 811x1000 | C21: =IF('ORDER SHEET'!$L$12="OR","OR","-") -> - | D21: ='ORDER SHEET'!$R$12 -> 1
C22: ='ORDER SHEET'!$M$12 -> SILVER | D22: ='ORDER SHEET'!$P$12 -> R | E22: ='ORDER SHEET'!$C$12 -> 6 OF 18
A23: ='ORDER SHEET'!$A$12 -> BLINDS4U | B23: ='ORDER SHEET'!$B$12 -> Chris | C23: ='ORDER SHEET'!$I$12 & " " & 'ORDER SHEET'!$J$12 -> SOLARCOOL 5% BEIGE GREY | D23: ='ORDER SHEET'!$Q$12 -> M
D24: ='ORDER SHEET'!$O$12 -> 750 | E24: ='ORDER SHEET'!$N$12&" "&"ACC" -> S WHITE ACC
A25: ='ORDER SHEET'!$E$13 -> Bed1/2 | B25: ='ORDER SHEET'!$F$13&"x"&'ORDER SHEET'!$G$13 -> 811x1000 | C25: =IF('ORDER SHEET'!$L$13="OR","OR","-") -> - | D25: ='ORDER SHEET'!$R$13 -> 1
C26: ='ORDER SHEET'!$M$13 -> SILVER | D26: ='ORDER SHEET'!$P$13 -> L | E26: ='ORDER SHEET'!$C$13 -> 7 OF 18
A27: ='ORDER SHEET'!$A$13 -> BLINDS4U | B27: ='ORDER SHEET'!$B$13 -> Chris | C27: ='ORDER SHEET'!$I$13 & " " & 'ORDER SHEET'!$J$13 -> SOLARCOOL 5% BEIGE GREY | D27: ='ORDER SHEET'!$Q$13 -> M
D28: ='ORDER SHEET'!$O$13 -> 750 | E28: ='ORDER SHEET'!$N$13&" "&"ACC" -> S WHITE ACC
A29: ='ORDER SHEET'!$E$14 -> Bed 2 | B29: ='ORDER SHEET'!$F$14&"x"&'ORDER SHEET'!$G$14 -> 1762x1200 | C29: =IF('ORDER SHEET'!$L$14="OR","OR","-") -> - | D29: ='ORDER SHEET'!$R$14 -> 1
C30: ='ORDER SHEET'!$M$14 -> SILVER | D30: ='ORDER SHEET'!$P$14 -> R | E30: ='ORDER SHEET'!$C$14 -> 8 OF 18
A31: ='ORDER SHEET'!$A$14 -> BLINDS4U | B31: ='ORDER SHEET'!$B$14 -> Chris | C31: ='ORDER SHEET'!$I$14 & " " & 'ORDER SHEET'!$J$14 -> SOLARCOOL 5% BEIGE GREY | D31: ='ORDER SHEET'!$Q$14 -> M
D32: ='ORDER SHEET'!$O$14 -> 750 | E32: ='ORDER SHEET'!$N$14&" "&"ACC" -> S WHITE ACC
A33: ='ORDER SHEET'!$E$15 -> Lg1/1 | B33: ='ORDER SHEET'!$F$15&"x"&'ORDER SHEET'!$G$15 -> 975x1800 | C33: =IF('ORDER SHEET'!$L$15="OR","OR","-") -> - | D33: ='ORDER SHEET'!$R$15 -> 1
C34: ='ORDER SHEET'!$M$15 -> SILVER | D34: ='ORDER SHEET'!$P$15 -> R | E34: ='ORDER SHEET'!$C$15 -> 9 OF 18
A35: ='ORDER SHEET'!$A$15 -> BLINDS4U | B35: ='ORDER SHEET'!$B$15 -> Chris | C35: ='ORDER SHEET'!$I$15 & " " & 'ORDER SHEET'!$J$15 -> VIBE Terrace | D35: ='ORDER SHEET'!$Q$15 -> M
D36: ='ORDER SHEET'!$O$15 -> 750 | E36: ='ORDER SHEET'!$N$15&" "&"ACC" -> S WHITE ACC
A37: ='ORDER SHEET'!$E$16 -> Lg1/2 | B37: ='ORDER SHEET'!$F$16&"x"&'ORDER SHEET'!$G$16 -> 975x1800 | C37: =IF('ORDER SHEET'!$L$16="OR","OR","-") -> - | D37: ='ORDER SHEET'!$R$16 -> 1
C38: ='ORDER SHEET'!$M$16 -> SILVER | D38: ='ORDER SHEET'!$P$16 -> R | E38: ='ORDER SHEET'!$C$16 -> 10 OF 18
A39: ='ORDER SHEET'!$A$16 -> BLINDS4U | B39: ='ORDER SHEET'!$B$16 -> Chris | C39: ='ORDER SHEET'!$I$16 & " " & 'ORDER SHEET'!$J$16 -> VIBE Terrace | D39: ='ORDER SHEET'!$Q$16 -> M
D40: ='ORDER SHEET'!$O$16 -> 750 | E40: ='ORDER SHEET'!$N$16&" "&"ACC" -> S WHITE ACC
...

Sheet Materials
A1: Material | B1: Price List Name | Q1: Old Materials
A2: 6th Avenue | B2: Group 5 | Q2: Essence | R2: Group 7
A3: Aquila | B3: Group 5 | Q3: Tempo | R3: Group 5
A4: Aruba | B4: Group 4 | Q4: Elements | R4: Group 6
A5: Aspen | B5: Group 4 | Q5: Echo | R5: Group 7
A6: Aura | B6: Group 1 | Q6: Tuscany | R6: Group 5
A7: Balmoral | B7: Group 5 | Q7: Fraser | R7: Group 4
A8: Barbados | B8: Group 4
A9: Bauhaus | B9: Group 5 | Q9: Matka | R9: Group 5
A10: Belice | B10: Group 4 | Q10: Comet | R10: Group 5
A11: Boston II | B11: Group 5 | Q11: Hyatt | R11: Group 7
A12: Broome II | B12: Group 5 | Q12: Icon | R12: Group 2
A13: Buxton | B13: Group 4
A14: Castille | B14: Group 4 | Q14: Dawn | R14: Group 2
A15: Chatsworth | B15: Group 3 | Q15: Aruba | R15: Group 4
A16: Concord II | B16: Group 5 | Q16: Katoomba | R16: Group 7
A17: Dawn | B17: Group 2
A18: Dawn Pearlised & Mini | B18: Group 3 | Q18: Broome | R18: Group 5
A19: Duo Block | B19: Group 2
A20: Duo Screen | B20: Group 3 | Q20: Plaza Plus | R20: Group 3
A21: E Screen | B21: Group 5 | Q21: Sunbloc | R21: Group 4
A22: Ecolibrium 4300 | B22: Group 4 | Q22: Scarborough | R22: Group 6
A23: Ecolibrium 4500 | B23: Group 4 | Q23: Shaw Duo Block | R23: Group 2
A24: Ecolibrium 4510 | B24: Group 4 | Q24: Shaw Vibe Metallic | R24: Group 2
A25: Evolution | B25: Group 3 | Q25: Buxton | R25: Group 4
A26: Flo | B26: Group 1 | Q26: Uniline Sunset | R26: Group 2
A27: Focus | B27: Group 2
A28: Fraser | B28: Group 4
A29: Gala | B29: Group 5 | Q29: Husk II | R29: Group 4
A30: Husk | B30: Group 4 | Q30: Elegance | R30: Group 2
A31: Icon FR | B31: Group 4 | Q31: Clovelly | R31: Group 5
A32: Jersey | B32: Group 4 | Q32: Dawn Perlized | R32: Group 3
A33: Karma | B33: Group 3 | Q33: Aspen | R33: Group 4
A34: Kew | B34: Group 4
A35: Le Reve | B35: Group 3
A36: Linesque | B36: Group 3 | Q36: 6th Avenue | R36: Group 5
A37: Linx | B37: Group 5 | Q37: Tremont | R37: Group 5
A38: Lite Screen 10% | B38: Lite Screen | Q38: Zara | R38: Group 4
A39: Lite Screen 5% | B39: Lite Screen | Q39: Yukon | R39: Group 5
A40: M Screen | B40: Group 5 | Q40: St Lucia | R40: Group 4
...
